<sdf version='1.6'>
  <world name='default'>
    <plugin name='ros_link_attacher_plugin' filename='libgazebo_ros_link_attacher.so'/>
    <light name='sun' type='directional'>
      <cast_shadows>1</cast_shadows>
      <pose frame=''>0 0 10 0 -0 0</pose>
      <diffuse>0.8 0.8 0.8 1</diffuse>
      <specular>0.2 0.2 0.2 1</specular>
      <attenuation>
        <range>1000</range>
        <constant>0.9</constant>
        <linear>0.01</linear>
        <quadratic>0.001</quadratic>
      </attenuation>
      <direction>-0.5 0.1 -0.9</direction>
    </light>
    <model name='ground_plane'>
      <static>1</static>
      <link name='link'>
        <collision name='collision'>
          <geometry>
            <plane>
              <normal>0 0 1</normal>
              <size>100 100</size>
            </plane>
          </geometry>
          <surface>
            <contact>
              <collide_bitmask>65535</collide_bitmask>
              <ode/>
            </contact>
            <friction>
              <ode>
                <mu>100</mu>
                <mu2>50</mu2>
              </ode>
              <torsional>
                <ode/>
              </torsional>
            </friction>
            <bounce/>
          </surface>
          <max_contacts>10</max_contacts>
        </collision>
        <visual name='visual'>
          <cast_shadows>0</cast_shadows>
          <geometry>
            <plane>
              <normal>0 0 1</normal>
              <size>100 100</size>
            </plane>
          </geometry>
          <material>
            <script>
              <uri>file://media/materials/scripts/gazebo.material</uri>
              <name>Gazebo/Grey</name>
            </script>
          </material>
        </visual>
        <self_collide>0</self_collide>
        <enable_wind>0</enable_wind>
        <kinematic>0</kinematic>
      </link>
    </model>
    <model name='office'>
      <static>1</static>
      <link name='link'>
        <collision name='colision1'>
          <geometry>
            <mesh>
              <uri>model://office/meshes/SB_fixed.obj</uri>
            </mesh>
          </geometry>
          <max_contacts>10</max_contacts>
          <surface>
            <contact>
              <ode/>
            </contact>
            <bounce/>
            <friction>
              <torsional>
                <ode/>
              </torsional>
              <ode/>
            </friction>
          </surface>
        </collision>
        <visual name='visual1'>
          <cast_shadows>1</cast_shadows>
          <geometry>
            <mesh>
              <uri>model://office/meshes/SB_fixed.obj</uri>
            </mesh>
          </geometry>
        </visual>
        <self_collide>0</self_collide>
        <enable_wind>0</enable_wind>
        <kinematic>0</kinematic>
      </link>
      <pose frame=''>0 0 0.08 0 -0 0</pose>
    </model>
    <model name='dropbox'>
      <link name='link_0'>
        <pose frame=''>0 -0 0 0 0 -1.56873</pose>
        <inertial>
          <mass>1</mass>
          <inertia>
            <ixx>0.166667</ixx>
            <ixy>0</ixy>
            <ixz>0</ixz>
            <iyy>0.166667</iyy>
            <iyz>0</iyz>
            <izz>0.166667</izz>
          </inertia>
        </inertial>
        <visual name='visual'>
          <pose frame=''>0 0 0 0 -0 0</pose>
          <geometry>
            <mesh>
              <uri>model://dropbox/meshes/dropbox.dae</uri>
              <scale>1 1 1</scale>
            </mesh>
          </geometry>
          <material>
            <lighting>1</lighting>
            <script>
              <uri>file://media/materials/scripts/gazebo.material</uri>
              <name>Gazebo/Blue</name>
            </script>
            <ambient>0.3 0.3 0.3 1</ambient>
            <diffuse>0.7 0.7 0.7 1</diffuse>
            <specular>0.01 0.01 0.01 1</specular>
            <emissive>0 0 1 1</emissive>
          </material>
          <transparency>0</transparency>
          <cast_shadows>1</cast_shadows>
        </visual>
        <collision name='collision'>
          <laser_retro>0</laser_retro>
          <max_contacts>10</max_contacts>
          <pose frame=''>0 0 0 0 -0 0</pose>
          <geometry>
            <mesh>
              <uri>model://dropbox/meshes/dropbox.dae</uri>
              <scale>1 1 1</scale>
            </mesh>
          </geometry>
          <surface>
            <friction>
              <ode>
                <mu>1</mu>
                <mu2>1</mu2>
                <fdir1>0 0 0</fdir1>
                <slip1>0</slip1>
                <slip2>0</slip2>
              </ode>
              <torsional>
                <coefficient>1</coefficient>
                <patch_radius>0</patch_radius>
                <surface_radius>0</surface_radius>
                <use_patch_radius>1</use_patch_radius>
                <ode>
                  <slip>0</slip>
                </ode>
              </torsional>
            </friction>
            <bounce>
              <restitution_coefficient>0</restitution_coefficient>
              <threshold>1e+06</threshold>
            </bounce>
            <contact>
              <collide_without_contact>0</collide_without_contact>
              <collide_without_contact_bitmask>1</collide_without_contact_bitmask>
              <collide_bitmask>1</collide_bitmask>
              <ode>
                <soft_cfm>0</soft_cfm>
                <soft_erp>0.2</soft_erp>
                <kp>1e+13</kp>
                <kd>1</kd>
                <max_vel>0.01</max_vel>
                <min_depth>0</min_depth>
              </ode>
              <bullet>
                <split_impulse>1</split_impulse>
                <split_impulse_penetration_threshold>-0.01</split_impulse_penetration_threshold>
                <soft_cfm>0</soft_cfm>
                <soft_erp>0.2</soft_erp>
                <kp>1e+13</kp>
                <kd>1</kd>
              </bullet>
            </contact>
          </surface>
        </collision>
        <self_collide>0</self_collide>
        <enable_wind>0</enable_wind>
        <kinematic>0</kinematic>
      </link>
      <static>1</static>
      <allow_auto_disable>1</allow_auto_disable>
      <pose frame=''>8.2 2.64 0.08 0 0 -1.6</pose>
    </model>
    <model name='table'>
      <static>1</static>
      <link name='link'>
        <collision name='surface'>
          <pose frame=''>0 0 1 0 -0 0</pose>
          <geometry>
            <box>
              <size>1.5 0.8 0.03</size>
            </box>
          </geometry>
          <surface>
            <friction>
              <ode>
                <mu>0.6</mu>
                <mu2>0.6</mu2>
              </ode>
              <torsional>
                <ode/>
              </torsional>
            </friction>
            <contact>
              <ode/>
            </contact>
            <bounce/>
          </surface>
          <max_contacts>10</max_contacts>
        </collision>
        <visual name='visual1'>
          <pose frame=''>0 0 1 0 -0 0</pose>
          <geometry>
            <box>
              <size>1.5 0.8 0.03</size>
            </box>
          </geometry>
          <material>
            <script>
              <uri>file://media/materials/scripts/gazebo.material</uri>
              <name>Gazebo/Wood</name>
            </script>
          </material>
        </visual>
        <collision name='front_left_leg'>
          <pose frame=''>0.68 0.38 0.5 0 -0 0</pose>
          <geometry>
            <cylinder>
              <radius>0.02</radius>
              <length>1</length>
            </cylinder>
          </geometry>
          <max_contacts>10</max_contacts>
          <surface>
            <contact>
              <ode/>
            </contact>
            <bounce/>
            <friction>
              <torsional>
                <ode/>
              </torsional>
              <ode/>
            </friction>
          </surface>
        </collision>
        <visual name='front_left_leg'>
          <pose frame=''>0.68 0.38 0.5 0 -0 0</pose>
          <geometry>
            <cylinder>
              <radius>0.02</radius>
              <length>1</length>
            </cylinder>
          </geometry>
          <material>
            <script>
              <uri>file://media/materials/scripts/gazebo.material</uri>
              <name>Gazebo/Grey</name>
            </script>
          </material>
        </visual>
        <collision name='front_right_leg'>
          <pose frame=''>0.68 -0.38 0.5 0 -0 0</pose>
          <geometry>
            <cylinder>
              <radius>0.02</radius>
              <length>1</length>
            </cylinder>
          </geometry>
          <max_contacts>10</max_contacts>
          <surface>
            <contact>
              <ode/>
            </contact>
            <bounce/>
            <friction>
              <torsional>
                <ode/>
              </torsional>
              <ode/>
            </friction>
          </surface>
        </collision>
        <visual name='front_right_leg'>
          <pose frame=''>0.68 -0.38 0.5 0 -0 0</pose>
          <geometry>
            <cylinder>
              <radius>0.02</radius>
              <length>1</length>
            </cylinder>
          </geometry>
          <material>
            <script>
              <uri>file://media/materials/scripts/gazebo.material</uri>
              <name>Gazebo/Grey</name>
            </script>
          </material>
        </visual>
        <collision name='back_right_leg'>
          <pose frame=''>-0.68 -0.38 0.5 0 -0 0</pose>
          <geometry>
            <cylinder>
              <radius>0.02</radius>
              <length>1</length>
            </cylinder>
          </geometry>
          <max_contacts>10</max_contacts>
          <surface>
            <contact>
              <ode/>
            </contact>
            <bounce/>
            <friction>
              <torsional>
                <ode/>
              </torsional>
              <ode/>
            </friction>
          </surface>
        </collision>
        <visual name='back_right_leg'>
          <pose frame=''>-0.68 -0.38 0.5 0 -0 0</pose>
          <geometry>
            <cylinder>
              <radius>0.02</radius>
              <length>1</length>
            </cylinder>
          </geometry>
          <material>
            <script>
              <uri>file://media/materials/scripts/gazebo.material</uri>
              <name>Gazebo/Grey</name>
            </script>
          </material>
        </visual>
        <collision name='back_left_leg'>
          <pose frame=''>-0.68 0.38 0.5 0 -0 0</pose>
          <geometry>
            <cylinder>
              <radius>0.02</radius>
              <length>1</length>
            </cylinder>
          </geometry>
          <max_contacts>10</max_contacts>
          <surface>
            <contact>
              <ode/>
            </contact>
            <bounce/>
            <friction>
              <torsional>
                <ode/>
              </torsional>
              <ode/>
            </friction>
          </surface>
        </collision>
        <visual name='back_left_leg'>
          <pose frame=''>-0.68 0.38 0.5 0 -0 0</pose>
          <geometry>
            <cylinder>
              <radius>0.02</radius>
              <length>1</length>
            </cylinder>
          </geometry>
          <material>
            <script>
              <uri>file://media/materials/scripts/gazebo.material</uri>
              <name>Gazebo/Grey</name>
            </script>
          </material>
        </visual>
        <self_collide>0</self_collide>
        <enable_wind>0</enable_wind>
        <kinematic>0</kinematic>
      </link>
      <pose frame=''>26.608 -3.569 0 0 -0 0.934</pose>
    </model>
    <gravity>0 0 -9.8</gravity>
    <magnetic_field>6e-06 2.3e-05 -4.2e-05</magnetic_field>
    <atmosphere type='adiabatic'/>
    <physics name='default_physics' default='0' type='ode'>
      <max_step_size>0.001</max_step_size>
      <real_time_factor>1</real_time_factor>
      <real_time_update_rate>1000</real_time_update_rate>
    </physics>
    <scene>
      <ambient>0.4 0.4 0.4 1</ambient>
      <background>0.7 0.7 0.7 1</background>
      <shadows>1</shadows>
    </scene>
    <wind/>
    <spherical_coordinates>
      <surface_model>EARTH_WGS84</surface_model>
      <latitude_deg>0</latitude_deg>
      <longitude_deg>0</longitude_deg>
      <elevation>0</elevation>
      <heading_deg>0</heading_deg>
    </spherical_coordinates>
    <model name='coke_can'>
      <link name='link'>
        <inertial>
          <pose frame=''>0 0 0.06 0 -0 0</pose>
          <mass>0.39</mass>
          <inertia>
            <ixx>0.00055575</ixx>
            <ixy>0</ixy>
            <ixz>0</ixz>
            <iyy>0.00055575</iyy>
            <iyz>0</iyz>
            <izz>0.0001755</izz>
          </inertia>
        </inertial>
        <collision name='collision'>
          <pose frame=''>0.003937 0.004724 -0.18 0 -0 0</pose>
          <geometry>
            <mesh>
              <uri>model://coke_can/meshes/coke_can.dae</uri>
            </mesh>
          </geometry>
          <surface>
            <friction>
              <ode>
                <mu>1</mu>
                <mu2>1</mu2>
              </ode>
              <torsional>
                <ode/>
              </torsional>
            </friction>
            <contact>
              <ode>
                <kp>1e+07</kp>
                <kd>1</kd>
                <min_depth>0.001</min_depth>
                <max_vel>0.1</max_vel>
              </ode>
            </contact>
            <bounce/>
          </surface>
          <max_contacts>10</max_contacts>
        </collision>
        <visual name='visual'>
          <pose frame=''>0.003937 0.004724 -0.18 0 -0 0</pose>
          <geometry>
            <mesh>
              <uri>model://coke_can/meshes/coke_can.dae</uri>
            </mesh>
          </geometry>
        </visual>
        <self_collide>0</self_collide>
        <enable_wind>0</enable_wind>
        <kinematic>0</kinematic>
      </link>
      <pose frame=''>7.84 3.24 0.87 0 -0 0</pose>
    </model>
    <model name='battery'>
      <link name='soap2_link'>
        <inertial>
          <pose frame=''>0 0 0 0 -0 0</pose>
          <mass>0.08</mass>
          <inertia>
            <ixx>1</ixx>
            <ixy>0</ixy>
            <ixz>0</ixz>
            <iyy>1</iyy>
            <iyz>0</iyz>
            <izz>1</izz>
          </inertia>
        </inertial>
        <visual name='soap2_visual'>
          <pose frame=''>0 0 0 0 -0 0</pose>
          <material>
            <script>
              <uri>model://soap2/materials/scripts</uri>
              <uri>model://soap2/materials/textures</uri>
              <name>soap2</name>
            </script>
          </material>
          <geometry>
            <mesh>
              <uri>model://soap2/meshes/soap2.dae</uri>
            </mesh>
          </geometry>
        </visual>
        <collision name='soap2_collision'>
          <pose frame=''>-0.002 0.00502 0.05 0 0 -1</pose>
          <geometry>
            <box>
              <size>0.065 0.04 0.105</size>
            </box>
          </geometry>
          <max_contacts>10</max_contacts>
          <surface>
            <contact>
              <ode/>
            </contact>
            <bounce/>
            <friction>
              <torsional>
                <ode/>
              </torsional>
              <ode/>
            </friction>
          </surface>
        </collision>
        <self_collide>0</self_collide>
        <enable_wind>0</enable_wind>
        <kinematic>0</kinematic>
      </link>
      <pose frame=''>8.10856 3.23928 0.87 0 -0 0</pose>
    </model>
    <model name='ebot'>
      <link name='ebot_base'>
        <pose frame=''>0 0 0 0 -0 0</pose>
        <inertial>
          <pose frame=''>0.000941 2e-06 0.169965 0 -0 0</pose>
          <mass>32.2426</mass>
          <inertia>
            <ixx>0.926622</ixx>
            <ixy>-5.5986e-05</ixy>
            <ixz>0.000783927</ixz>
            <iyy>1.52745</iyy>
            <iyz>8.09706e-06</iyz>
            <izz>1.03278</izz>
          </inertia>
        </inertial>
        <collision name='ebot_base_collision'>
          <pose frame=''>0 0 0.12 0 -0 0</pose>
          <geometry>
            <box>
              <size>0.585 0.3 0.25</size>
            </box>
          </geometry>
          <surface>
            <contact>
              <ode/>
            </contact>
            <friction>
              <ode/>
              <torsional>
                <ode/>
              </torsional>
            </friction>
            <bounce/>
          </surface>
          <max_contacts>10</max_contacts>
        </collision>
        <collision name='ebot_base_fixed_joint_lump__FUS1_collision_1'>
          <pose frame=''>0.297826 -0.157279 0.097726 -1.5708 0 0.006797</pose>
          <geometry>
            <box>
              <size>0.019 0.057 0.028</size>
            </box>
          </geometry>
          <max_contacts>10</max_contacts>
          <surface>
            <contact>
              <ode/>
            </contact>
            <bounce/>
            <friction>
              <torsional>
                <ode/>
              </torsional>
              <ode/>
            </friction>
          </surface>
        </collision>
        <collision name='ebot_base_fixed_joint_lump__FUS2_collision_2'>
          <pose frame=''>0.295787 0.142714 0.097726 -1.5708 0 0.006797</pose>
          <geometry>
            <box>
              <size>0.019 0.057 0.028</size>
            </box>
          </geometry>
          <max_contacts>10</max_contacts>
          <surface>
            <contact>
              <ode/>
            </contact>
            <bounce/>
            <friction>
              <torsional>
                <ode/>
              </torsional>
              <ode/>
            </friction>
          </surface>
        </collision>
        <collision name='ebot_base_fixed_joint_lump__FUS3_collision_3'>
          <pose frame=''>0.272749 -0.074948 0.042475 0 0.785398 0.006797</pose>
          <geometry>
            <box>
              <size>0.019 0.057 0.028</size>
            </box>
          </geometry>
          <max_contacts>10</max_contacts>
          <surface>
            <contact>
              <ode/>
            </contact>
            <bounce/>
            <friction>
              <torsional>
                <ode/>
              </torsional>
              <ode/>
            </friction>
          </surface>
        </collision>
        <collision name='ebot_base_fixed_joint_lump__FUS4_collision_4'>
          <pose frame=''>0.271702 0.079049 0.042475 0 0.785398 0.006797</pose>
          <geometry>
            <box>
              <size>0.019 0.057 0.028</size>
            </box>
          </geometry>
          <max_contacts>10</max_contacts>
          <surface>
            <contact>
              <ode/>
            </contact>
            <bounce/>
            <friction>
              <torsional>
                <ode/>
              </torsional>
              <ode/>
            </friction>
          </surface>
        </collision>
        <collision name='ebot_base_fixed_joint_lump__LHUS10_collision_5'>
          <pose frame=''>0.14046 0.10004 0.196076 0.001869 0.123098 0.799849</pose>
          <geometry>
            <box>
              <size>0.019 0.057 0.028</size>
            </box>
          </geometry>
          <max_contacts>10</max_contacts>
          <surface>
            <contact>
              <ode/>
            </contact>
            <bounce/>
            <friction>
              <torsional>
                <ode/>
              </torsional>
              <ode/>
            </friction>
          </surface>
        </collision>
        <collision name='ebot_base_fixed_joint_lump__LHUS9_collision_6'>
          <pose frame=''>-0.180601 0.145976 0.18945 0 -0 1.57759</pose>
          <geometry>
            <box>
              <size>0.019 0.057 0.028</size>
            </box>
          </geometry>
          <max_contacts>10</max_contacts>
          <surface>
            <contact>
              <ode/>
            </contact>
            <bounce/>
            <friction>
              <torsional>
                <ode/>
              </torsional>
              <ode/>
            </friction>
          </surface>
        </collision>
        <collision name='ebot_base_fixed_joint_lump__RHUS7_collision_7'>
          <pose frame=''>-0.178602 -0.148017 0.18945 0 0 -1.564</pose>
          <geometry>
            <box>
              <size>0.019 0.057 0.028</size>
            </box>
          </geometry>
          <max_contacts>10</max_contacts>
          <surface>
            <contact>
              <ode/>
            </contact>
            <bounce/>
            <friction>
              <torsional>
                <ode/>
              </torsional>
              <ode/>
            </friction>
          </surface>
        </collision>
        <collision name='ebot_base_fixed_joint_lump__RHUS9_collision_8'>
          <pose frame=''>0.141804 -0.097722 0.196076 -0.001869 0.123098 -0.786255</pose>
          <geometry>
            <box>
              <size>0.019 0.057 0.028</size>
            </box>
          </geometry>
          <max_contacts>10</max_contacts>
          <surface>
            <contact>
              <ode/>
            </contact>
            <bounce/>
            <friction>
              <torsional>
                <ode/>
              </torsional>
              <ode/>
            </friction>
          </surface>
        </collision>
        <collision name='ebot_base_fixed_joint_lump__RUS5_collision_9'>
          <pose frame=''>-0.295329 0.157696 0.097703 -1.5708 0 -3.1348</pose>
          <geometry>
            <box>
              <size>0.019 0.057 0.028</size>
            </box>
          </geometry>
          <max_contacts>10</max_contacts>
          <surface>
            <contact>
              <ode/>
            </contact>
            <bounce/>
            <friction>
              <torsional>
                <ode/>
              </torsional>
              <ode/>
            </friction>
          </surface>
        </collision>
        <collision name='ebot_base_fixed_joint_lump__RUS6_collision_10'>
          <pose frame=''>-0.29329 -0.142297 0.097703 -1.5708 0 -3.1348</pose>
          <geometry>
            <box>
              <size>0.019 0.057 0.028</size>
            </box>
          </geometry>
          <max_contacts>10</max_contacts>
          <surface>
            <contact>
              <ode/>
            </contact>
            <bounce/>
            <friction>
              <torsional>
                <ode/>
              </torsional>
              <ode/>
            </friction>
          </surface>
        </collision>
        <collision name='ebot_base_fixed_joint_lump__base_link_collision_11'>
          <pose frame=''>0 0 0.521 0 -0 0</pose>
          <geometry>
            <cylinder>
              <length>0.024</length>
              <radius>0.0735</radius>
            </cylinder>
          </geometry>
          <max_contacts>10</max_contacts>
          <surface>
            <contact>
              <ode/>
            </contact>
            <bounce/>
            <friction>
              <torsional>
                <ode/>
              </torsional>
              <ode/>
            </friction>
          </surface>
        </collision>
        <collision name='ebot_base_fixed_joint_lump__imu_link_collision_12'>
          <pose frame=''>0 0 0.2 0 -0 0</pose>
          <geometry>
            <box>
              <size>0.02 0.015 0.008</size>
            </box>
          </geometry>
          <surface>
            <contact>
              <ode/>
            </contact>
            <friction>
              <ode/>
              <torsional>
                <ode/>
              </torsional>
            </friction>
            <bounce/>
          </surface>
          <max_contacts>10</max_contacts>
        </collision>
        <collision name='ebot_base_fixed_joint_lump__camera_link_collision_13'>
          <pose frame=''>0.297944 0.002084 0.023051 0 -0 0</pose>
          <geometry>
            <box>
              <size>0.001 0.001 0.001</size>
            </box>
          </geometry>
          <surface>
            <contact>
              <ode/>
            </contact>
            <friction>
              <ode/>
              <torsional>
                <ode/>
              </torsional>
            </friction>
            <bounce/>
          </surface>
          <max_contacts>10</max_contacts>
        </collision>
        <collision name='ebot_base_fixed_joint_lump__laser_collision_14'>
          <pose frame=''>0.255541 0 0.18 0 -0 0.006797</pose>
          <geometry>
            <cylinder>
              <length>0.04</length>
              <radius>0.03</radius>
            </cylinder>
          </geometry>
          <surface>
            <contact>
              <ode/>
            </contact>
            <friction>
              <ode/>
              <torsional>
                <ode/>
              </torsional>
            </friction>
            <bounce/>
          </surface>
          <max_contacts>10</max_contacts>
        </collision>
        <visual name='ebot_base_visual'>
          <pose frame=''>0 0 0 0 -0 0</pose>
          <geometry>
            <mesh>
              <scale>1 1 1</scale>
              <uri>/home/kartik/catkin_ws/src/sahayak_bot/sahayak_bot/ebot_description/meshes/chassis.STL</uri>
            </mesh>
          </geometry>
          <material>
            <script>
              <name>Gazebo/Grey</name>
              <uri>file://media/materials/scripts/gazebo.material</uri>
            </script>
          </material>
        </visual>
        <visual name='ebot_base_fixed_joint_lump__FUS1_visual_1'>
          <pose frame=''>0.297826 -0.157279 0.097726 -1.5708 0 0.006797</pose>
          <geometry>
            <mesh>
              <scale>1 1 1</scale>
              <uri>/home/kartik/catkin_ws/src/sahayak_bot/sahayak_bot/ebot_description/meshes/FUS1.STL</uri>
            </mesh>
          </geometry>
        </visual>
        <visual name='ebot_base_fixed_joint_lump__FUS2_visual_2'>
          <pose frame=''>0.295787 0.142714 0.097726 -1.5708 0 0.006797</pose>
          <geometry>
            <mesh>
              <scale>1 1 1</scale>
              <uri>/home/kartik/catkin_ws/src/sahayak_bot/sahayak_bot/ebot_description/meshes/FUS2.STL</uri>
            </mesh>
          </geometry>
        </visual>
        <visual name='ebot_base_fixed_joint_lump__FUS3_visual_3'>
          <pose frame=''>0.272749 -0.074948 0.042475 0 0.785398 0.006797</pose>
          <geometry>
            <mesh>
              <scale>1 1 1</scale>
              <uri>/home/kartik/catkin_ws/src/sahayak_bot/sahayak_bot/ebot_description/meshes/FUS3.STL</uri>
            </mesh>
          </geometry>
        </visual>
        <visual name='ebot_base_fixed_joint_lump__FUS4_visual_4'>
          <pose frame=''>0.271702 0.079049 0.042475 0 0.785398 0.006797</pose>
          <geometry>
            <mesh>
              <scale>1 1 1</scale>
              <uri>/home/kartik/catkin_ws/src/sahayak_bot/sahayak_bot/ebot_description/meshes/FUS4.STL</uri>
            </mesh>
          </geometry>
        </visual>
        <visual name='ebot_base_fixed_joint_lump__LHUS10_visual_5'>
          <pose frame=''>0.14046 0.10004 0.196076 0.001869 0.123098 0.799849</pose>
          <geometry>
            <mesh>
              <scale>1 1 1</scale>
              <uri>/home/kartik/catkin_ws/src/sahayak_bot/sahayak_bot/ebot_description/meshes/LHUS10.STL</uri>
            </mesh>
          </geometry>
        </visual>
        <visual name='ebot_base_fixed_joint_lump__LHUS9_visual_6'>
          <pose frame=''>-0.180601 0.145976 0.18945 0 -0 1.57759</pose>
          <geometry>
            <mesh>
              <scale>1 1 1</scale>
              <uri>/home/kartik/catkin_ws/src/sahayak_bot/sahayak_bot/ebot_description/meshes/LHUS9.STL</uri>
            </mesh>
          </geometry>
        </visual>
        <visual name='ebot_base_fixed_joint_lump__RHUS7_visual_7'>
          <pose frame=''>-0.178602 -0.148017 0.18945 0 0 -1.564</pose>
          <geometry>
            <mesh>
              <scale>1 1 1</scale>
              <uri>/home/kartik/catkin_ws/src/sahayak_bot/sahayak_bot/ebot_description/meshes/RHUS7.STL</uri>
            </mesh>
          </geometry>
        </visual>
        <visual name='ebot_base_fixed_joint_lump__RHUS9_visual_8'>
          <pose frame=''>0.141804 -0.097722 0.196076 -0.001869 0.123098 -0.786255</pose>
          <geometry>
            <mesh>
              <scale>1 1 1</scale>
              <uri>/home/kartik/catkin_ws/src/sahayak_bot/sahayak_bot/ebot_description/meshes/RHUS9.STL</uri>
            </mesh>
          </geometry>
        </visual>
        <visual name='ebot_base_fixed_joint_lump__RUS5_visual_9'>
          <pose frame=''>-0.295329 0.157696 0.097703 -1.5708 0 -3.1348</pose>
          <geometry>
            <mesh>
              <scale>1 1 1</scale>
              <uri>/home/kartik/catkin_ws/src/sahayak_bot/sahayak_bot/ebot_description/meshes/RUS5.STL</uri>
            </mesh>
          </geometry>
        </visual>
        <visual name='ebot_base_fixed_joint_lump__RUS6_visual_10'>
          <pose frame=''>-0.29329 -0.142297 0.097703 -1.5708 0 -3.1348</pose>
          <geometry>
            <mesh>
              <scale>1 1 1</scale>
              <uri>/home/kartik/catkin_ws/src/sahayak_bot/sahayak_bot/ebot_description/meshes/RUS6.STL</uri>
            </mesh>
          </geometry>
        </visual>
        <visual name='ebot_base_fixed_joint_lump__base_link_visual_11'>
          <pose frame=''>0 0 0.521 0 -0 0</pose>
          <geometry>
            <mesh>
              <scale>1 1 1</scale>
              <uri>/home/kartik/catkin_ws/src/sahayak_bot/sahayak_bot/ur_description/meshes/ur5/visual/base.dae</uri>
            </mesh>
          </geometry>
        </visual>
        <visual name='ebot_base_fixed_joint_lump__imu_link_visual_12'>
          <pose frame=''>0 0 0.2 0 -0 0</pose>
          <geometry>
            <box>
              <size>0.02 0.015 0.008</size>
            </box>
          </geometry>
          <material>
            <script>
              <uri>__default__</uri>
              <name>__default__</name>
            </script>
          </material>
        </visual>
        <visual name='ebot_base_fixed_joint_lump__camera_link_visual_13'>
          <pose frame=''>0.277944 0.002084 0.023051 1.5707 0 1.5707</pose>
          <geometry>
            <mesh>
              <scale>1 1 1</scale>
              <uri>/home/kartik/catkin_ws/src/sahayak_bot/sahayak_bot/ebot_description/meshes/NAVRS.STL</uri>
            </mesh>
          </geometry>
          <material>
            <script>
              <name>Gazebo/Black</name>
              <uri>file://media/materials/scripts/gazebo.material</uri>
            </script>
          </material>
        </visual>
        <visual name='ebot_base_fixed_joint_lump__laser_visual_14'>
          <pose frame=''>0.255541 0 0.18 0 -0 0.006797</pose>
          <geometry>
            <cylinder>
              <length>0.04</length>
              <radius>0.03</radius>
            </cylinder>
          </geometry>
          <material>
            <script>
              <name>Gazebo/Black</name>
              <uri>file://media/materials/scripts/gazebo.material</uri>
            </script>
          </material>
        </visual>
        <velocity_decay/>
        <velocity_decay/>
        <sensor name='imu_sensor' type='imu'>
          <always_on>1</always_on>
          <update_rate>100</update_rate>
          <visualize>1</visualize>
          <topic>__default_topic__</topic>
          <plugin name='imu_plugin' filename='libgazebo_ros_imu_sensor.so'>
            <topicName>imu</topicName>
            <bodyName>imu_link</bodyName>
            <updateRateHZ>10.0</updateRateHZ>
            <gaussianNoise>0.0</gaussianNoise>
            <xyzOffset>0 0 0</xyzOffset>
            <rpyOffset>0 0 0</rpyOffset>
            <frameName>imu_link</frameName>
            <initialOrientationAsReference>0</initialOrientationAsReference>
            <robotNamespace>/</robotNamespace>
          </plugin>
          <pose frame=''>0 0 0.2 0 -0 0</pose>
          <imu/>
        </sensor>
        <velocity_decay/>
        <velocity_decay/>
        <sensor name='intelrealsenseD435i' type='depth'>
          <always_on>1</always_on>
          <visualize>1</visualize>
          <camera name='__default__'>
            <horizontal_fov>1.047</horizontal_fov>
            <image>
              <width>640</width>
              <height>480</height>
              <format>R8G8B8</format>
            </image>
            <depth_camera>
              <output>depths</output>
            </depth_camera>
            <clip>
              <near>0.1</near>
              <far>100</far>
            </clip>
          </camera>
          <plugin name='intelrealsense' filename='libgazebo_ros_openni_kinect.so'>
            <alwaysOn>1</alwaysOn>
            <updateRate>10.0</updateRate>
            <cameraName>camera</cameraName>
            <frameName>camera_depth_frame</frameName>
            <imageTopicName>/camera/color/image_raw</imageTopicName>
            <depthImageTopicName>/camera/depth/image_rect_raw</depthImageTopicName>
            <pointCloudTopicName>depth/points</pointCloudTopicName>
            <cameraInfoTopicName>/camera/color/camera_info</cameraInfoTopicName>
            <depthImageCameraInfoTopicName>/camera/depth/camera_info</depthImageCameraInfoTopicName>
            <pointCloudCutoff>0.2</pointCloudCutoff>
            <pointCloudCutoffMax>10.0</pointCloudCutoffMax>
            <hackBaseline>0.07</hackBaseline>
            <distortionK1>0.0</distortionK1>
            <distortionK2>0.0</distortionK2>
            <distortionK3>0.0</distortionK3>
            <distortionT1>0.0</distortionT1>
            <distortionT2>0.0</distortionT2>
            <CxPrime>0.0</CxPrime>
            <Cx>0.0</Cx>
            <Cy>0.0</Cy>
            <focalLength>0.0</focalLength>
            <robotNamespace>/</robotNamespace>
          </plugin>
          <pose frame=''>0.277944 0.002084 0.023051 0 -0 0</pose>
        </sensor>
        <gravity>1</gravity>
        <velocity_decay/>
        <gravity>1</gravity>
        <velocity_decay/>
        <sensor name='head_rplidar_sensor' type='ray'>
          <visualize>0</visualize>
          <update_rate>40</update_rate>
          <ray>
            <scan>
              <horizontal>
                <samples>720</samples>
                <resolution>1</resolution>
                <min_angle>-2.35619</min_angle>
                <max_angle>2.35619</max_angle>
              </horizontal>
              <vertical>
                <samples>1</samples>
                <min_angle>0</min_angle>
                <max_angle>0</max_angle>
              </vertical>
            </scan>
            <range>
              <min>0.5</min>
              <max>20</max>
              <resolution>0.01</resolution>
            </range>
            <noise>
              <type>gaussian</type>
              <mean>0</mean>
              <stddev>0.01</stddev>
            </noise>
          </ray>
          <plugin name='gazebo_ros_head_rplidar_controller' filename='libgazebo_ros_laser.so'>
            <topicName>/ebot/laser/scan</topicName>
            <frameName>laser</frameName>
            <robotNamespace>/</robotNamespace>
          </plugin>
          <pose frame=''>0.255541 0 0.18 0 -0 0.006797</pose>
        </sensor>
        <self_collide>0</self_collide>
        <enable_wind>0</enable_wind>
        <kinematic>0</kinematic>
      </link>
      <link name='FWL'>
        <pose frame=''>0.199948 0.192163 0.045 0 -0 0.006797</pose>
        <inertial>
          <pose frame=''>6.7e-05 0.025016 -1e-06 0 -0 0</pose>
          <mass>0.7</mass>
          <inertia>
            <ixx>0.003</ixx>
            <ixy>0</ixy>
            <ixz>0</ixz>
            <iyy>0.003</iyy>
            <iyz>0</iyz>
            <izz>0.0035</izz>
          </inertia>
        </inertial>
        <collision name='FWL_collision'>
          <pose frame=''>0 0.025 0 -3.14159 1.57079 1.57079</pose>
          <geometry>
            <cylinder>
              <length>0.05</length>
              <radius>0.1</radius>
            </cylinder>
          </geometry>
          <surface>
            <contact>
              <ode/>
            </contact>
            <friction>
              <ode/>
              <torsional>
                <ode/>
              </torsional>
            </friction>
            <bounce/>
          </surface>
          <max_contacts>10</max_contacts>
        </collision>
        <visual name='FWL_visual'>
          <pose frame=''>0 0 0 0 -0 0</pose>
          <geometry>
            <mesh>
              <scale>1 1 1</scale>
              <uri>/home/kartik/catkin_ws/src/sahayak_bot/sahayak_bot/ebot_description/meshes/FWL.STL</uri>
            </mesh>
          </geometry>
          <material>
            <script>
              <name>Gazebo/Black</name>
              <uri>file://media/materials/scripts/gazebo.material</uri>
            </script>
          </material>
        </visual>
        <gravity>1</gravity>
        <velocity_decay/>
        <self_collide>0</self_collide>
        <enable_wind>0</enable_wind>
        <kinematic>0</kinematic>
      </link>
      <joint name='FWLJ' type='revolute'>
        <child>FWL</child>
        <parent>ebot_base</parent>
        <axis>
          <xyz>-0.006797 0.999977 0</xyz>
          <limit>
            <lower>-1e+16</lower>
            <upper>1e+16</upper>
          </limit>
          <dynamics>
            <spring_reference>0</spring_reference>
            <spring_stiffness>0</spring_stiffness>
          </dynamics>
          <use_parent_model_frame>1</use_parent_model_frame>
        </axis>
      </joint>
      <link name='FWR'>
        <pose frame=''>0.20254 -0.189028 0.045 -3.14159 0.911096 0.006797</pose>
        <inertial>
          <pose frame=''>6.7e-05 0.025016 -1e-06 0 -0 0</pose>
          <mass>0.7</mass>
          <inertia>
            <ixx>0.003</ixx>
            <ixy>0</ixy>
            <ixz>0</ixz>
            <iyy>0.003</iyy>
            <iyz>0</iyz>
            <izz>0.0035</izz>
          </inertia>
        </inertial>
        <collision name='FWR_collision'>
          <pose frame=''>0 0.025 0 -3.14159 1.57079 1.57079</pose>
          <geometry>
            <cylinder>
              <length>0.05</length>
              <radius>0.1</radius>
            </cylinder>
          </geometry>
          <surface>
            <contact>
              <ode/>
            </contact>
            <friction>
              <ode/>
              <torsional>
                <ode/>
              </torsional>
            </friction>
            <bounce/>
          </surface>
          <max_contacts>10</max_contacts>
        </collision>
        <visual name='FWR_visual'>
          <pose frame=''>0 0 0 0 -0 0</pose>
          <geometry>
            <mesh>
              <scale>1 1 1</scale>
              <uri>/home/kartik/catkin_ws/src/sahayak_bot/sahayak_bot/ebot_description/meshes/FWR.STL</uri>
            </mesh>
          </geometry>
          <material>
            <script>
              <name>Gazebo/Black</name>
              <uri>file://media/materials/scripts/gazebo.material</uri>
            </script>
          </material>
        </visual>
        <gravity>1</gravity>
        <velocity_decay/>
        <self_collide>0</self_collide>
        <enable_wind>0</enable_wind>
        <kinematic>0</kinematic>
      </link>
      <joint name='FWRJ' type='revolute'>
        <child>FWR</child>
        <parent>ebot_base</parent>
        <axis>
          <xyz>-0.006797 0.999977 0</xyz>
          <limit>
            <lower>-1e+16</lower>
            <upper>1e+16</upper>
          </limit>
          <dynamics>
            <spring_reference>0</spring_reference>
            <spring_stiffness>0</spring_stiffness>
          </dynamics>
          <use_parent_model_frame>1</use_parent_model_frame>
        </axis>
      </joint>
      <link name='RWL'>
        <pose frame=''>-0.200042 0.189445 0.045 0 -0 0.006797</pose>
        <inertial>
          <pose frame=''>6.7e-05 0.025016 -1e-06 0 -0 0</pose>
          <mass>0.7</mass>
          <inertia>
            <ixx>0.003</ixx>
            <ixy>0</ixy>
            <ixz>0</ixz>
            <iyy>0.003</iyy>
            <iyz>0</iyz>
            <izz>0.0035</izz>
          </inertia>
        </inertial>
        <collision name='RWL_collision'>
          <pose frame=''>0 0.025 0 -3.14159 1.57079 1.57079</pose>
          <geometry>
            <cylinder>
              <length>0.05</length>
              <radius>0.1</radius>
            </cylinder>
          </geometry>
          <surface>
            <contact>
              <ode/>
            </contact>
            <friction>
              <ode/>
              <torsional>
                <ode/>
              </torsional>
            </friction>
            <bounce/>
          </surface>
          <max_contacts>10</max_contacts>
        </collision>
        <visual name='RWL_visual'>
          <pose frame=''>0 0 0 0 -0 0</pose>
          <geometry>
            <mesh>
              <scale>1 1 1</scale>
              <uri>/home/kartik/catkin_ws/src/sahayak_bot/sahayak_bot/ebot_description/meshes/RWL.STL</uri>
            </mesh>
          </geometry>
          <material>
            <script>
              <name>Gazebo/Black</name>
              <uri>file://media/materials/scripts/gazebo.material</uri>
            </script>
          </material>
        </visual>
        <gravity>1</gravity>
        <velocity_decay/>
        <self_collide>0</self_collide>
        <enable_wind>0</enable_wind>
        <kinematic>0</kinematic>
      </link>
      <joint name='RWLJ' type='revolute'>
        <child>RWL</child>
        <parent>ebot_base</parent>
        <axis>
          <xyz>-0.006797 0.999977 0</xyz>
          <limit>
            <lower>-1e+16</lower>
            <upper>1e+16</upper>
          </limit>
          <dynamics>
            <spring_reference>0</spring_reference>
            <spring_stiffness>0</spring_stiffness>
          </dynamics>
          <use_parent_model_frame>1</use_parent_model_frame>
        </axis>
      </joint>
      <link name='RWR'>
        <pose frame=''>-0.197451 -0.191747 0.045 -3.14159 0.544912 0.006797</pose>
        <inertial>
          <pose frame=''>6.7e-05 0.025016 -1e-06 0 -0 0</pose>
          <mass>0.7</mass>
          <inertia>
            <ixx>0.003</ixx>
            <ixy>0</ixy>
            <ixz>0</ixz>
            <iyy>0.003</iyy>
            <iyz>0</iyz>
            <izz>0.0035</izz>
          </inertia>
        </inertial>
        <collision name='RWR_collision'>
          <pose frame=''>0 0.025 0 -3.14159 1.57079 1.57079</pose>
          <geometry>
            <cylinder>
              <length>0.05</length>
              <radius>0.1</radius>
            </cylinder>
          </geometry>
          <surface>
            <contact>
              <ode/>
            </contact>
            <friction>
              <ode/>
              <torsional>
                <ode/>
              </torsional>
            </friction>
            <bounce/>
          </surface>
          <max_contacts>10</max_contacts>
        </collision>
        <visual name='RWR_visual'>
          <pose frame=''>0 0 0 0 -0 0</pose>
          <geometry>
            <mesh>
              <scale>1 1 1</scale>
              <uri>/home/kartik/catkin_ws/src/sahayak_bot/sahayak_bot/ebot_description/meshes/RWR.STL</uri>
            </mesh>
          </geometry>
          <material>
            <script>
              <name>Gazebo/Black</name>
              <uri>file://media/materials/scripts/gazebo.material</uri>
            </script>
          </material>
        </visual>
        <gravity>1</gravity>
        <velocity_decay/>
        <self_collide>0</self_collide>
        <enable_wind>0</enable_wind>
        <kinematic>0</kinematic>
      </link>
      <joint name='RWRJ' type='revolute'>
        <child>RWR</child>
        <parent>ebot_base</parent>
        <axis>
          <xyz>-0.006797 0.999977 0</xyz>
          <limit>
            <lower>-1e+16</lower>
            <upper>1e+16</upper>
          </limit>
          <dynamics>
            <spring_reference>0</spring_reference>
            <spring_stiffness>0</spring_stiffness>
          </dynamics>
          <use_parent_model_frame>1</use_parent_model_frame>
        </axis>
      </joint>
      <link name='shoulder_link'>
        <pose frame=''>0 0 0.610159 0 -0 0</pose>
        <inertial>
          <pose frame=''>0 0 0 0 -0 0</pose>
          <mass>3.7</mass>
          <inertia>
            <ixx>0.0102675</ixx>
            <ixy>0</ixy>
            <ixz>0</ixz>
            <iyy>0.0102675</iyy>
            <iyz>0</iyz>
            <izz>0.00666</izz>
          </inertia>
        </inertial>
        <collision name='shoulder_link_collision'>
          <pose frame=''>0 0 0 0 -0 0</pose>
          <geometry>
            <cylinder>
              <length>0.134</length>
              <radius>0.0595</radius>
            </cylinder>
          </geometry>
          <surface>
            <contact>
              <ode/>
            </contact>
            <friction>
              <ode/>
              <torsional>
                <ode/>
              </torsional>
            </friction>
            <bounce/>
          </surface>
          <max_contacts>10</max_contacts>
        </collision>
        <visual name='shoulder_link_visual'>
          <pose frame=''>0 0 0 0 -0 0</pose>
          <geometry>
            <mesh>
              <scale>1 1 1</scale>
              <uri>/home/kartik/catkin_ws/src/sahayak_bot/sahayak_bot/ur_description/meshes/ur5/visual/shoulder.dae</uri>
            </mesh>
          </geometry>
          <material>
            <script>
              <uri>__default__</uri>
              <name>__default__</name>
            </script>
          </material>
        </visual>
        <gravity>1</gravity>
        <velocity_decay/>
        <self_collide>1</self_collide>
        <enable_wind>0</enable_wind>
        <kinematic>0</kinematic>
      </link>
      <joint name='shoulder_pan_joint' type='revolute'>
        <child>shoulder_link</child>
        <parent>ebot_base</parent>
        <axis>
          <xyz>0 0 1</xyz>
          <limit>
            <lower>-6.28319</lower>
            <upper>6.28319</upper>
            <effort>150</effort>
            <velocity>3.15</velocity>
          </limit>
          <dynamics>
            <damping>0</damping>
            <friction>0</friction>
            <spring_reference>0</spring_reference>
            <spring_stiffness>0</spring_stiffness>
          </dynamics>
          <use_parent_model_frame>1</use_parent_model_frame>
        </axis>
      </joint>
      <link name='upper_arm_link'>
        <pose frame=''>0 0.13585 0.610159 0 -0 0</pose>
        <inertial>
          <pose frame=''>0 0 0.28 0 -0 0</pose>
          <mass>8.393</mass>
          <inertia>
            <ixx>0.226891</ixx>
            <ixy>0</ixy>
            <ixz>0</ixz>
            <iyy>0.226891</iyy>
            <iyz>0</iyz>
            <izz>0.0151074</izz>
          </inertia>
        </inertial>
        <collision name='upper_arm_link_collision'>
          <pose frame=''>0 0 0.22 0 -0 0</pose>
          <geometry>
            <cylinder>
              <length>0.545</length>
              <radius>0.045</radius>
            </cylinder>
          </geometry>
          <surface>
            <contact>
              <ode/>
            </contact>
            <friction>
              <ode/>
              <torsional>
                <ode/>
              </torsional>
            </friction>
            <bounce/>
          </surface>
          <max_contacts>10</max_contacts>
        </collision>
        <visual name='upper_arm_link_visual'>
          <pose frame=''>0 0 0 0 -0 0</pose>
          <geometry>
            <mesh>
              <scale>1 1 1</scale>
              <uri>/home/kartik/catkin_ws/src/sahayak_bot/sahayak_bot/ur_description/meshes/ur5/visual/upperarm.dae</uri>
            </mesh>
          </geometry>
          <material>
            <script>
              <uri>__default__</uri>
              <name>__default__</name>
            </script>
          </material>
        </visual>
        <gravity>1</gravity>
        <velocity_decay/>
        <self_collide>1</self_collide>
        <enable_wind>0</enable_wind>
        <kinematic>0</kinematic>
      </link>
      <joint name='shoulder_lift_joint' type='revolute'>
        <child>upper_arm_link</child>
        <parent>shoulder_link</parent>
        <axis>
          <xyz>0 1 0</xyz>
          <limit>
            <lower>-6.28319</lower>
            <upper>6.28319</upper>
            <effort>150</effort>
            <velocity>3.15</velocity>
          </limit>
          <dynamics>
            <damping>0</damping>
            <friction>0</friction>
            <spring_reference>0</spring_reference>
            <spring_stiffness>0</spring_stiffness>
          </dynamics>
          <use_parent_model_frame>1</use_parent_model_frame>
        </axis>
      </joint>
      <link name='forearm_link'>
        <pose frame=''>0 0.01615 1.03516 3.14159 1.0472 3.14159</pose>
        <inertial>
          <pose frame=''>0 0 0.196125 0 -0 0</pose>
          <mass>2.275</mass>
          <inertia>
            <ixx>0.0312168</ixx>
            <ixy>0</ixy>
            <ixz>0</ixz>
            <iyy>0.0312168</iyy>
            <iyz>0</iyz>
            <izz>0.004095</izz>
          </inertia>
        </inertial>
        <collision name='forearm_link_collision'>
          <pose frame=''>0 0 0.18 0 -0 0</pose>
          <geometry>
            <cylinder>
              <length>0.489</length>
              <radius>0.038</radius>
            </cylinder>
          </geometry>
          <surface>
            <contact>
              <ode/>
            </contact>
            <friction>
              <ode/>
              <torsional>
                <ode/>
              </torsional>
            </friction>
            <bounce/>
          </surface>
          <max_contacts>10</max_contacts>
        </collision>
        <visual name='forearm_link_visual'>
          <pose frame=''>0 0 0 0 -0 0</pose>
          <geometry>
            <mesh>
              <scale>1 1 1</scale>
              <uri>/home/kartik/catkin_ws/src/sahayak_bot/sahayak_bot/ur_description/meshes/ur5/visual/forearm.dae</uri>
            </mesh>
          </geometry>
          <material>
            <script>
              <uri>__default__</uri>
              <name>__default__</name>
            </script>
          </material>
        </visual>
        <gravity>1</gravity>
        <velocity_decay/>
        <self_collide>1</self_collide>
        <enable_wind>0</enable_wind>
        <kinematic>0</kinematic>
      </link>
      <joint name='elbow_joint' type='revolute'>
        <child>forearm_link</child>
        <parent>upper_arm_link</parent>
        <axis>
          <xyz>0 1 0</xyz>
          <limit>
            <lower>-3.14159</lower>
            <upper>3.14159</upper>
            <effort>150</effort>
            <velocity>3.15</velocity>
          </limit>
          <dynamics>
            <damping>0</damping>
            <friction>0</friction>
            <spring_reference>0</spring_reference>
            <spring_stiffness>0</spring_stiffness>
          </dynamics>
          <use_parent_model_frame>1</use_parent_model_frame>
        </axis>
      </joint>
      <link name='wrist_1_link'>
        <pose frame=''>0.339698 0.01615 0.839034 3.14159 -0.523599 3.14159</pose>
        <inertial>
          <pose frame=''>0 0.093 0 0 -0 0</pose>
          <mass>1.219</mass>
          <inertia>
            <ixx>0.0025599</ixx>
            <ixy>0</ixy>
            <ixz>0</ixz>
            <iyy>0.0025599</iyy>
            <iyz>0</iyz>
            <izz>0.0021942</izz>
          </inertia>
        </inertial>
        <collision name='wrist_1_link_collision'>
          <pose frame=''>0 0.093 0.008 0 -0 0</pose>
          <geometry>
            <cylinder>
              <length>0.1</length>
              <radius>0.032</radius>
            </cylinder>
          </geometry>
          <surface>
            <contact>
              <ode/>
            </contact>
            <friction>
              <ode/>
              <torsional>
                <ode/>
              </torsional>
            </friction>
            <bounce/>
          </surface>
          <max_contacts>10</max_contacts>
        </collision>
        <visual name='wrist_1_link_visual'>
          <pose frame=''>0 0 0 0 -0 0</pose>
          <geometry>
            <mesh>
              <scale>1 1 1</scale>
              <uri>/home/kartik/catkin_ws/src/sahayak_bot/sahayak_bot/ur_description/meshes/ur5/visual/wrist1.dae</uri>
            </mesh>
          </geometry>
          <material>
            <script>
              <uri>__default__</uri>
              <name>__default__</name>
            </script>
          </material>
        </visual>
        <gravity>1</gravity>
        <velocity_decay/>
        <self_collide>1</self_collide>
        <enable_wind>0</enable_wind>
        <kinematic>0</kinematic>
      </link>
      <joint name='wrist_1_joint' type='revolute'>
        <child>wrist_1_link</child>
        <parent>forearm_link</parent>
        <axis>
          <xyz>0 1 0</xyz>
          <limit>
            <lower>-6.28319</lower>
            <upper>6.28319</upper>
            <effort>28</effort>
            <velocity>3.2</velocity>
          </limit>
          <dynamics>
            <damping>0</damping>
            <friction>0</friction>
            <spring_reference>0</spring_reference>
            <spring_stiffness>0</spring_stiffness>
          </dynamics>
          <use_parent_model_frame>1</use_parent_model_frame>
        </axis>
      </joint>
      <link name='wrist_2_link'>
        <pose frame=''>0.339698 0.10915 0.839034 3.14159 -0.523599 3.14159</pose>
        <inertial>
          <pose frame=''>0 0 0.09465 0 -0 0</pose>
          <mass>1.219</mass>
          <inertia>
            <ixx>0.0025599</ixx>
            <ixy>0</ixy>
            <ixz>0</ixz>
            <iyy>0.0025599</iyy>
            <iyz>0</iyz>
            <izz>0.0021942</izz>
          </inertia>
        </inertial>
        <collision name='wrist_2_link_collision'>
          <pose frame=''>0 0 0.09465 1.57 -0 0</pose>
          <geometry>
            <cylinder>
              <length>0.105</length>
              <radius>0.032</radius>
            </cylinder>
          </geometry>
          <surface>
            <contact>
              <ode/>
            </contact>
            <friction>
              <ode/>
              <torsional>
                <ode/>
              </torsional>
            </friction>
            <bounce/>
          </surface>
          <max_contacts>10</max_contacts>
        </collision>
        <visual name='wrist_2_link_visual'>
          <pose frame=''>0 0 0 0 -0 0</pose>
          <geometry>
            <mesh>
              <scale>1 1 1</scale>
              <uri>/home/kartik/catkin_ws/src/sahayak_bot/sahayak_bot/ur_description/meshes/ur5/visual/wrist2.dae</uri>
            </mesh>
          </geometry>
          <material>
            <script>
              <uri>__default__</uri>
              <name>__default__</name>
            </script>
          </material>
        </visual>
        <gravity>1</gravity>
        <velocity_decay/>
        <self_collide>1</self_collide>
        <enable_wind>0</enable_wind>
        <kinematic>0</kinematic>
      </link>
      <joint name='wrist_2_joint' type='revolute'>
        <child>wrist_2_link</child>
        <parent>wrist_1_link</parent>
        <axis>
          <xyz>-0.5 0 -0.866025</xyz>
          <limit>
            <lower>-6.28319</lower>
            <upper>6.28319</upper>
            <effort>28</effort>
            <velocity>3.2</velocity>
          </limit>
          <dynamics>
            <damping>0</damping>
            <friction>0</friction>
            <spring_reference>0</spring_reference>
            <spring_stiffness>0</spring_stiffness>
          </dynamics>
          <use_parent_model_frame>1</use_parent_model_frame>
        </axis>
      </joint>
      <link name='wrist_3_link'>
        <pose frame=''>0.292373 0.10915 0.757065 3.14159 -0.523599 3.14159</pose>
        <inertial>
          <pose frame=''>0 0.092039 -1e-06 1.5708 -0 0</pose>
          <mass>0.824861</mass>
          <inertia>
            <ixx>0.001372</ixx>
            <ixy>-1.75029e-26</ixy>
            <ixz>3.57451e-15</ixz>
            <iyy>0.00143293</iyy>
            <iyz>-6.36917e-09</iyz>
            <izz>0.000512181</izz>
          </inertia>
        </inertial>
        <collision name='wrist_3_link_collision'>
          <pose frame=''>0 0.067 0 1.57 -0 0</pose>
          <geometry>
            <cylinder>
              <length>0.0245</length>
              <radius>0.032</radius>
            </cylinder>
          </geometry>
          <surface>
            <contact>
              <ode/>
            </contact>
            <friction>
              <ode/>
              <torsional>
                <ode/>
              </torsional>
            </friction>
            <bounce/>
          </surface>
          <max_contacts>10</max_contacts>
        </collision>
        <collision name='wrist_3_link_fixed_joint_lump__ee_link_collision_1'>
          <pose frame=''>-0 0.0723 0 0 -0 1.5708</pose>
          <geometry>
            <box>
              <size>0.01 0.01 0.01</size>
            </box>
          </geometry>
          <surface>
            <contact>
              <ode/>
            </contact>
            <friction>
              <ode/>
              <torsional>
                <ode/>
              </torsional>
            </friction>
            <bounce/>
          </surface>
          <max_contacts>10</max_contacts>
        </collision>
        <collision name='wrist_3_link_fixed_joint_lump__gripper_base_link_collision_2'>
          <pose frame=''>0 0.117 0 3.14159 1.57079 -1.57079</pose>
          <geometry>
            <cylinder>
              <length>0.03</length>
              <radius>0.0375</radius>
            </cylinder>
          </geometry>
          <surface>
            <contact>
              <ode>
                <kp>1e+08</kp>
                <kd>1</kd>
              </ode>
            </contact>
            <friction>
              <ode>
                <mu>100000</mu>
                <mu2>100000</mu2>
              </ode>
              <torsional>
                <ode/>
              </torsional>
            </friction>
            <bounce/>
          </surface>
          <max_contacts>10</max_contacts>
        </collision>
        <collision name='wrist_3_link_fixed_joint_lump__camera_link2_collision_3'>
          <pose frame=''>1.6e-05 0.12 -0.08 3.14 0 1.57</pose>
          <geometry>
            <box>
              <size>0.001 0.001 0.001</size>
            </box>
          </geometry>
          <surface>
            <contact>
              <ode/>
            </contact>
            <friction>
              <ode/>
              <torsional>
                <ode/>
              </torsional>
            </friction>
            <bounce/>
          </surface>
          <max_contacts>10</max_contacts>
        </collision>
        <visual name='wrist_3_link_visual'>
          <pose frame=''>0 0 0 0 -0 0</pose>
          <geometry>
            <mesh>
              <scale>1 1 1</scale>
              <uri>/home/kartik/catkin_ws/src/sahayak_bot/sahayak_bot/ur_description/meshes/ur5/visual/wrist3.dae</uri>
            </mesh>
          </geometry>
          <material>
            <script>
              <uri>__default__</uri>
              <name>__default__</name>
            </script>
          </material>
        </visual>
        <visual name='wrist_3_link_fixed_joint_lump__gripper_base_link_visual_1'>
          <pose frame=''>0 0.1 0 0 -0 1.5708</pose>
          <geometry>
            <mesh>
              <scale>1 1 1</scale>
              <uri>/home/kartik/catkin_ws/src/sahayak_bot/sahayak_bot/robotiq_85_gripper-master/robotiq_85_description/meshes/visual/robotiq_85_base_link.dae</uri>
            </mesh>
          </geometry>
          <material>
            <script>
              <uri>__default__</uri>
              <name>__default__</name>
            </script>
          </material>
        </visual>
        <visual name='wrist_3_link_fixed_joint_lump__camera_link2_visual_2'>
          <pose frame=''>0 0.1 -0.08 -1.57089 -0.001593 -0.0007</pose>
          <geometry>
            <mesh>
              <scale>1 1 1</scale>
              <uri>/home/kartik/catkin_ws/src/sahayak_bot/sahayak_bot/ebot_description/meshes/NAVRS.STL</uri>
            </mesh>
          </geometry>
          <material>
            <script>
              <uri>__default__</uri>
              <name>__default__</name>
            </script>
          </material>
        </visual>
        <velocity_decay/>
        <velocity_decay/>
        <self_collide>1</self_collide>
        <velocity_decay/>
        <gravity>1</gravity>
        <velocity_decay/>
        <sensor name='intelrealsense2' type='depth'>
          <always_on>1</always_on>
          <visualize>1</visualize>
          <camera name='__default__'>
            <horizontal_fov>1.047</horizontal_fov>
            <image>
              <width>640</width>
              <height>480</height>
              <format>R8G8B8</format>
            </image>
            <depth_camera>
              <output>depths</output>
            </depth_camera>
            <clip>
              <near>0.1</near>
              <far>100</far>
            </clip>
          </camera>
          <plugin name='intelrealsense' filename='libgazebo_ros_openni_kinect.so'>
            <alwaysOn>1</alwaysOn>
            <updateRate>10.0</updateRate>
            <cameraName>camera2</cameraName>
            <frameName>camera_depth_frame2</frameName>
            <imageTopicName>/camera/color/image_raw2</imageTopicName>
            <depthImageTopicName>/camera/depth/image_raw2</depthImageTopicName>
            <pointCloudTopicName>depth/points2</pointCloudTopicName>
            <cameraInfoTopicName>/camera/color/camera_info2</cameraInfoTopicName>
            <depthImageCameraInfoTopicName>/camera/depth/camera_info2</depthImageCameraInfoTopicName>
            <pointCloudCutoff>0.2</pointCloudCutoff>
            <pointCloudCutoffMax>10.0</pointCloudCutoffMax>
            <hackBaseline>0.07</hackBaseline>
            <distortionK1>0.0</distortionK1>
            <distortionK2>0.0</distortionK2>
            <distortionK3>0.0</distortionK3>
            <distortionT1>0.0</distortionT1>
            <distortionT2>0.0</distortionT2>
            <CxPrime>0.0</CxPrime>
            <Cx>0.0</Cx>
            <Cy>0.0</Cy>
            <focalLength>0.0</focalLength>
            <robotNamespace>/</robotNamespace>
          </plugin>
          <pose frame=''>0 0.1 -0.08 3.14 0 1.57</pose>
        </sensor>
        <enable_wind>0</enable_wind>
        <kinematic>0</kinematic>
      </link>
      <joint name='wrist_3_joint' type='revolute'>
        <child>wrist_3_link</child>
        <parent>wrist_2_link</parent>
        <axis>
          <xyz>0 1 0</xyz>
          <limit>
            <lower>-6.28319</lower>
            <upper>6.28319</upper>
            <effort>28</effort>
            <velocity>3.2</velocity>
          </limit>
          <dynamics>
            <damping>0</damping>
            <friction>0</friction>
            <spring_reference>0</spring_reference>
            <spring_stiffness>0</spring_stiffness>
          </dynamics>
          <use_parent_model_frame>1</use_parent_model_frame>
        </axis>
      </joint>
      <link name='gripper_finger1_inner_knuckle_link'>
        <pose frame=''>0.303372 0.27057 0.750715 0.523599 -0 1.5708</pose>
        <inertial>
          <pose frame=''>0 0 0 0 -0 0</pose>
          <mass>0.029951</mass>
          <inertia>
            <ixx>3.9e-05</ixx>
            <ixy>0</ixy>
            <ixz>0</ixz>
            <iyy>5e-06</iyy>
            <iyz>0</iyz>
            <izz>3.5e-05</izz>
          </inertia>
        </inertial>
        <collision name='gripper_finger1_inner_knuckle_link_collision'>
          <pose frame=''>0.025 -0.02 0 0 0 -0.698</pose>
          <geometry>
            <box>
              <size>0.055 0.006 0.02</size>
            </box>
          </geometry>
          <surface>
            <contact>
              <ode>
                <kp>1e+08</kp>
                <kd>1</kd>
              </ode>
            </contact>
            <friction>
              <ode>
                <mu>100000</mu>
                <mu2>100000</mu2>
              </ode>
              <torsional>
                <ode/>
              </torsional>
            </friction>
            <bounce/>
          </surface>
          <max_contacts>10</max_contacts>
        </collision>
        <visual name='gripper_finger1_inner_knuckle_link_visual'>
          <pose frame=''>0 0 0 0 -0 0</pose>
          <geometry>
            <mesh>
              <scale>1 1 1</scale>
              <uri>/home/kartik/catkin_ws/src/sahayak_bot/sahayak_bot/robotiq_85_gripper-master/robotiq_85_description/meshes/visual/robotiq_85_inner_knuckle_link.dae</uri>
            </mesh>
          </geometry>
          <material>
            <script>
              <uri>__default__</uri>
              <name>__default__</name>
            </script>
          </material>
        </visual>
        <gravity>1</gravity>
        <velocity_decay/>
        <self_collide>0</self_collide>
        <enable_wind>0</enable_wind>
        <kinematic>0</kinematic>
      </link>
      <joint name='gripper_finger1_inner_knuckle_joint' type='revolute'>
        <child>gripper_finger1_inner_knuckle_link</child>
        <parent>wrist_3_link</parent>
        <axis>
          <xyz>0.5 -0 0.866025</xyz>
          <limit>
            <lower>-1e+16</lower>
            <upper>1e+16</upper>
          </limit>
          <dynamics>
            <spring_reference>0</spring_reference>
            <spring_stiffness>0</spring_stiffness>
          </dynamics>
          <use_parent_model_frame>1</use_parent_model_frame>
        </axis>
      </joint>
      <link name='gripper_finger1_finger_tip_link'>
        <pose frame=''>0.335934 0.31361 0.731915 0.523599 -0 1.5708</pose>
        <inertial>
          <pose frame=''>0 0 0 0 -0 0</pose>
          <mass>0.019555</mass>
          <inertia>
            <ixx>2e-06</ixx>
            <ixy>0</ixy>
            <ixz>0</ixz>
            <iyy>5e-06</iyy>
            <iyz>0</iyz>
            <izz>6e-06</izz>
          </inertia>
        </inertial>
        <collision name='gripper_finger1_finger_tip_link_collision'>
          <pose frame=''>0.02 0 0 0 -0 0</pose>
          <geometry>
            <box>
              <size>0.045 0.01 0.02</size>
            </box>
          </geometry>
          <surface>
            <contact>
              <ode>
                <kp>1e+08</kp>
                <kd>1</kd>
              </ode>
            </contact>
            <friction>
              <ode>
                <mu>100000</mu>
                <mu2>100000</mu2>
              </ode>
              <torsional>
                <ode/>
              </torsional>
            </friction>
            <bounce/>
          </surface>
          <max_contacts>10</max_contacts>
        </collision>
        <visual name='gripper_finger1_finger_tip_link_visual'>
          <pose frame=''>0 0 0 0 -0 0</pose>
          <geometry>
            <mesh>
              <scale>1 1 1</scale>
              <uri>/home/kartik/catkin_ws/src/sahayak_bot/sahayak_bot/robotiq_85_gripper-master/robotiq_85_description/meshes/visual/robotiq_85_finger_tip_link.dae</uri>
            </mesh>
          </geometry>
          <material>
            <script>
              <uri>__default__</uri>
              <name>__default__</name>
            </script>
          </material>
        </visual>
        <gravity>1</gravity>
        <velocity_decay/>
        <self_collide>0</self_collide>
        <enable_wind>0</enable_wind>
        <kinematic>0</kinematic>
      </link>
      <joint name='gripper_finger1_finger_tip_joint' type='revolute'>
        <child>gripper_finger1_finger_tip_link</child>
        <parent>gripper_finger1_inner_knuckle_link</parent>
        <axis>
          <xyz>0.5 -0 0.866025</xyz>
          <limit>
            <lower>-1e+16</lower>
            <upper>1e+16</upper>
          </limit>
          <dynamics>
            <spring_reference>0</spring_reference>
            <spring_stiffness>0</spring_stiffness>
          </dynamics>
          <use_parent_model_frame>1</use_parent_model_frame>
        </axis>
      </joint>
      <link name='gripper_finger1_knuckle_link'>
        <pose frame=''>0.318875 0.264055 0.741764 0.523599 -0 1.5708</pose>
        <inertial>
          <pose frame=''>-0.002436 -0.018774 0 0 -0 0</pose>
          <mass>0.0458</mass>
          <inertia>
            <ixx>2.29304e-05</ixx>
            <ixy>-4.4183e-06</ixy>
            <ixz>0</ixz>
            <iyy>2.2184e-05</iyy>
            <iyz>0</iyz>
            <izz>4.11145e-05</izz>
          </inertia>
        </inertial>
        <collision name='gripper_finger1_knuckle_link_collision'>
          <pose frame=''>0 -0.01 0 0 0 -0.0873</pose>
          <geometry>
            <box>
              <size>0.012 0.035 0.014</size>
            </box>
          </geometry>
          <surface>
            <contact>
              <ode>
                <kp>1e+08</kp>
                <kd>1</kd>
              </ode>
            </contact>
            <friction>
              <ode>
                <mu>100000</mu>
                <mu2>100000</mu2>
              </ode>
              <torsional>
                <ode/>
              </torsional>
            </friction>
            <bounce/>
          </surface>
          <max_contacts>10</max_contacts>
        </collision>
        <collision name='gripper_finger1_knuckle_link_fixed_joint_lump__gripper_finger1_finger_link_collision_1'>
          <pose frame=''>0.020915 -0.033486 0 0 0 -0.175</pose>
          <geometry>
            <box>
              <size>0.0591 0.01 0.02</size>
            </box>
          </geometry>
          <surface>
            <contact>
              <ode>
                <kp>1e+08</kp>
                <kd>1</kd>
              </ode>
            </contact>
            <friction>
              <ode>
                <mu>100000</mu>
                <mu2>100000</mu2>
              </ode>
              <torsional>
                <ode/>
              </torsional>
            </friction>
            <bounce/>
          </surface>
          <max_contacts>10</max_contacts>
        </collision>
        <visual name='gripper_finger1_knuckle_link_visual'>
          <pose frame=''>0 0 0 0 -0 0</pose>
          <geometry>
            <mesh>
              <scale>1 1 1</scale>
              <uri>/home/kartik/catkin_ws/src/sahayak_bot/sahayak_bot/robotiq_85_gripper-master/robotiq_85_description/meshes/visual/robotiq_85_knuckle_link.dae</uri>
            </mesh>
          </geometry>
          <material>
            <script>
              <uri>__default__</uri>
              <name>__default__</name>
            </script>
          </material>
        </visual>
        <visual name='gripper_finger1_knuckle_link_fixed_joint_lump__gripper_finger1_finger_link_visual_1'>
          <pose frame=''>-0.004086 -0.031486 0 0 -0 0</pose>
          <geometry>
            <mesh>
              <scale>1 1 1</scale>
              <uri>/home/kartik/catkin_ws/src/sahayak_bot/sahayak_bot/robotiq_85_gripper-master/robotiq_85_description/meshes/visual/robotiq_85_finger_link.dae</uri>
            </mesh>
          </geometry>
          <material>
            <script>
              <uri>__default__</uri>
              <name>__default__</name>
            </script>
          </material>
        </visual>
        <velocity_decay/>
        <gravity>1</gravity>
        <velocity_decay/>
        <self_collide>0</self_collide>
        <enable_wind>0</enable_wind>
        <kinematic>0</kinematic>
      </link>
      <joint name='gripper_finger1_joint' type='revolute'>
        <child>gripper_finger1_knuckle_link</child>
        <parent>wrist_3_link</parent>
        <axis>
          <xyz>0.5 -0 0.866025</xyz>
          <limit>
            <lower>0</lower>
            <upper>0.804</upper>
            <effort>1000</effort>
            <velocity>2</velocity>
          </limit>
          <dynamics>
            <spring_reference>0</spring_reference>
            <spring_stiffness>0</spring_stiffness>
          </dynamics>
          <use_parent_model_frame>1</use_parent_model_frame>
        </axis>
      </joint>
      <link name='gripper_finger2_inner_knuckle_link'>
        <pose frame=''>0.281375 0.27057 0.763415 -2.61799 0 1.5708</pose>
        <inertial>
          <pose frame=''>0 0 0 0 -0 0</pose>
          <mass>0.029951</mass>
          <inertia>
            <ixx>3.9e-05</ixx>
            <ixy>0</ixy>
            <ixz>0</ixz>
            <iyy>5e-06</iyy>
            <iyz>0</iyz>
            <izz>3.5e-05</izz>
          </inertia>
        </inertial>
        <collision name='gripper_finger2_inner_knuckle_link_collision'>
          <pose frame=''>0.025 -0.02 0 0 0 -0.698</pose>
          <geometry>
            <box>
              <size>0.055 0.006 0.02</size>
            </box>
          </geometry>
          <surface>
            <contact>
              <ode>
                <kp>1e+08</kp>
                <kd>1</kd>
              </ode>
            </contact>
            <friction>
              <ode>
                <mu>100000</mu>
                <mu2>100000</mu2>
              </ode>
              <torsional>
                <ode/>
              </torsional>
            </friction>
            <bounce/>
          </surface>
          <max_contacts>10</max_contacts>
        </collision>
        <visual name='gripper_finger2_inner_knuckle_link_visual'>
          <pose frame=''>0 0 0 0 -0 0</pose>
          <geometry>
            <mesh>
              <scale>1 1 1</scale>
              <uri>/home/kartik/catkin_ws/src/sahayak_bot/sahayak_bot/robotiq_85_gripper-master/robotiq_85_description/meshes/visual/robotiq_85_inner_knuckle_link.dae</uri>
            </mesh>
          </geometry>
          <material>
            <script>
              <uri>__default__</uri>
              <name>__default__</name>
            </script>
          </material>
        </visual>
        <gravity>1</gravity>
        <velocity_decay/>
        <self_collide>0</self_collide>
        <enable_wind>0</enable_wind>
        <kinematic>0</kinematic>
      </link>
      <joint name='gripper_finger2_inner_knuckle_joint' type='revolute'>
        <child>gripper_finger2_inner_knuckle_link</child>
        <parent>wrist_3_link</parent>
        <axis>
          <xyz>-0.5 0 -0.866025</xyz>
          <limit>
            <lower>-1e+16</lower>
            <upper>1e+16</upper>
          </limit>
          <dynamics>
            <spring_reference>0</spring_reference>
            <spring_stiffness>0</spring_stiffness>
          </dynamics>
          <use_parent_model_frame>1</use_parent_model_frame>
        </axis>
      </joint>
      <link name='gripper_finger2_finger_tip_link'>
        <pose frame=''>0.248813 0.31361 0.782214 -2.61799 0 1.5708</pose>
        <inertial>
          <pose frame=''>0 0 0 0 -0 0</pose>
          <mass>0.019555</mass>
          <inertia>
            <ixx>2e-06</ixx>
            <ixy>0</ixy>
            <ixz>0</ixz>
            <iyy>5e-06</iyy>
            <iyz>0</iyz>
            <izz>6e-06</izz>
          </inertia>
        </inertial>
        <collision name='gripper_finger2_finger_tip_link_collision'>
          <pose frame=''>0.02 0 0 0 -0 0</pose>
          <geometry>
            <box>
              <size>0.045 0.01 0.02</size>
            </box>
          </geometry>
          <surface>
            <contact>
              <ode>
                <kp>1e+08</kp>
                <kd>1</kd>
              </ode>
            </contact>
            <friction>
              <ode>
                <mu>100000</mu>
                <mu2>100000</mu2>
              </ode>
              <torsional>
                <ode/>
              </torsional>
            </friction>
            <bounce/>
          </surface>
          <max_contacts>10</max_contacts>
        </collision>
        <visual name='gripper_finger2_finger_tip_link_visual'>
          <pose frame=''>0 0 0 0 -0 0</pose>
          <geometry>
            <mesh>
              <scale>1 1 1</scale>
              <uri>/home/kartik/catkin_ws/src/sahayak_bot/sahayak_bot/robotiq_85_gripper-master/robotiq_85_description/meshes/visual/robotiq_85_finger_tip_link.dae</uri>
            </mesh>
          </geometry>
          <material>
            <script>
              <uri>__default__</uri>
              <name>__default__</name>
            </script>
          </material>
        </visual>
        <gravity>1</gravity>
        <velocity_decay/>
        <self_collide>0</self_collide>
        <enable_wind>0</enable_wind>
        <kinematic>0</kinematic>
      </link>
      <joint name='gripper_finger2_finger_tip_joint' type='revolute'>
        <child>gripper_finger2_finger_tip_link</child>
        <parent>gripper_finger2_inner_knuckle_link</parent>
        <axis>
          <xyz>-0.5 0 -0.866025</xyz>
          <limit>
            <lower>-1e+16</lower>
            <upper>1e+16</upper>
          </limit>
          <dynamics>
            <spring_reference>0</spring_reference>
            <spring_stiffness>0</spring_stiffness>
          </dynamics>
          <use_parent_model_frame>1</use_parent_model_frame>
        </axis>
      </joint>
      <link name='gripper_finger2_knuckle_link'>
        <pose frame=''>0.265872 0.264055 0.772365 -2.61799 0 1.5708</pose>
        <inertial>
          <pose frame=''>-0.002436 -0.018774 0 0 -0 0</pose>
          <mass>0.0458</mass>
          <inertia>
            <ixx>2.29304e-05</ixx>
            <ixy>-4.4183e-06</ixy>
            <ixz>0</ixz>
            <iyy>2.2184e-05</iyy>
            <iyz>0</iyz>
            <izz>4.11145e-05</izz>
          </inertia>
        </inertial>
        <collision name='gripper_finger2_knuckle_link_collision'>
          <pose frame=''>0 -0.01 0 0 0 -0.0873</pose>
          <geometry>
            <box>
              <size>0.012 0.035 0.014</size>
            </box>
          </geometry>
          <surface>
            <contact>
              <ode>
                <kp>1e+08</kp>
                <kd>1</kd>
              </ode>
            </contact>
            <friction>
              <ode>
                <mu>100000</mu>
                <mu2>100000</mu2>
              </ode>
              <torsional>
                <ode/>
              </torsional>
            </friction>
            <bounce/>
          </surface>
          <max_contacts>10</max_contacts>
        </collision>
        <collision name='gripper_finger2_knuckle_link_fixed_joint_lump__gripper_finger2_finger_link_collision_1'>
          <pose frame=''>0.020915 -0.033486 0 0 0 -0.175</pose>
          <geometry>
            <box>
              <size>0.0591 0.01 0.02</size>
            </box>
          </geometry>
          <surface>
            <contact>
              <ode>
                <kp>1e+08</kp>
                <kd>1</kd>
              </ode>
            </contact>
            <friction>
              <ode>
                <mu>100000</mu>
                <mu2>100000</mu2>
              </ode>
              <torsional>
                <ode/>
              </torsional>
            </friction>
            <bounce/>
          </surface>
          <max_contacts>10</max_contacts>
        </collision>
        <visual name='gripper_finger2_knuckle_link_visual'>
          <pose frame=''>0 0 0 0 -0 0</pose>
          <geometry>
            <mesh>
              <scale>1 1 1</scale>
              <uri>/home/kartik/catkin_ws/src/sahayak_bot/sahayak_bot/robotiq_85_gripper-master/robotiq_85_description/meshes/visual/robotiq_85_knuckle_link.dae</uri>
            </mesh>
          </geometry>
          <material>
            <script>
              <uri>__default__</uri>
              <name>__default__</name>
            </script>
          </material>
        </visual>
        <visual name='gripper_finger2_knuckle_link_fixed_joint_lump__gripper_finger2_finger_link_visual_1'>
          <pose frame=''>-0.004086 -0.031486 0 0 -0 0</pose>
          <geometry>
            <mesh>
              <scale>1 1 1</scale>
              <uri>/home/kartik/catkin_ws/src/sahayak_bot/sahayak_bot/robotiq_85_gripper-master/robotiq_85_description/meshes/visual/robotiq_85_finger_link.dae</uri>
            </mesh>
          </geometry>
          <material>
            <script>
              <uri>__default__</uri>
              <name>__default__</name>
            </script>
          </material>
        </visual>
        <velocity_decay/>
        <gravity>1</gravity>
        <velocity_decay/>
        <self_collide>0</self_collide>
        <enable_wind>0</enable_wind>
        <kinematic>0</kinematic>
      </link>
      <joint name='gripper_finger2_joint' type='revolute'>
        <child>gripper_finger2_knuckle_link</child>
        <parent>wrist_3_link</parent>
        <axis>
          <xyz>-0.5 0 -0.866025</xyz>
          <limit>
            <lower>-3.14</lower>
            <upper>3.14</upper>
            <effort>1000</effort>
            <velocity>100</velocity>
          </limit>
          <dynamics>
            <spring_reference>0</spring_reference>
            <spring_stiffness>0</spring_stiffness>
          </dynamics>
          <use_parent_model_frame>1</use_parent_model_frame>
        </axis>
      </joint>
      <plugin name='skid_steer_drive_controller' filename='libgazebo_ros_skid_steer_drive.so'>
        <updateRate>40.0</updateRate>
        <leftFrontJoint>FWLJ</leftFrontJoint>
        <rightFrontJoint>FWRJ</rightFrontJoint>
        <leftRearJoint>RWLJ</leftRearJoint>
        <rightRearJoint>RWRJ</rightRearJoint>
        <wheelSeparation>0.4</wheelSeparation>
        <wheelDiameter>0.2</wheelDiameter>
        <robotBaseFrame>ebot_base</robotBaseFrame>
        <torque>60</torque>
        <topicName>cmd_vel</topicName>
        <commandTopic>cmd_vel</commandTopic>
        <odometryTopic>odom</odometryTopic>
        <odometryFrame>odom</odometryFrame>
        <broadcastTF>1</broadcastTF>
        <robotNamespace>/</robotNamespace>
      </plugin>
      <plugin name='ros_control' filename='libgazebo_ros_control.so'>
        <robotNamespace>/</robotNamespace>
      </plugin>
      <plugin name='gazebo_grasp_fix' filename='libgazebo_grasp_fix.so'>
        <arm>
          <arm_name>gripper_arm</arm_name>
          <palm_link>wrist_3_link</palm_link>
          <gripper_link>gripper_finger1_finger_tip_link</gripper_link>
          <gripper_link>gripper_finger2_finger_tip_link</gripper_link>
        </arm>
        <forces_angle_tolerance>100</forces_angle_tolerance>
        <update_rate>2</update_rate>
        <grip_count_threshold>1</grip_count_threshold>
        <max_grip_count>2</max_grip_count>
        <release_tolerance>0.005</release_tolerance>
        <disable_collisions_on_attach>1</disable_collisions_on_attach>
        <contact_topic>__default_topic__</contact_topic>
        <robotNamespace>/</robotNamespace>
      </plugin>
      <static>0</static>
      <plugin name='mimic_robotiq_85_1' filename='libroboticsgroup_gazebo_mimic_joint_plugin.so'>
        <joint>gripper_finger1_joint</joint>
        <mimicJoint>gripper_finger2_joint</mimicJoint>
        <robotNamespace>/</robotNamespace>
      </plugin>
      <plugin name='mimic_robotiq_85_2' filename='libroboticsgroup_gazebo_mimic_joint_plugin.so'>
        <joint>gripper_finger1_joint</joint>
        <mimicJoint>gripper_finger2_inner_knuckle_joint</mimicJoint>
        <robotNamespace>/</robotNamespace>
      </plugin>
      <plugin name='mimic_robotiq_85_3' filename='libroboticsgroup_gazebo_mimic_joint_plugin.so'>
        <joint>gripper_finger1_joint</joint>
        <mimicJoint>gripper_finger1_inner_knuckle_joint</mimicJoint>
        <robotNamespace>/</robotNamespace>
      </plugin>
      <plugin name='mimic_robotiq_85_4' filename='libroboticsgroup_gazebo_mimic_joint_plugin.so'>
        <joint>gripper_finger1_joint</joint>
        <mimicJoint>gripper_finger1_finger_tip_joint</mimicJoint>
        <multiplier>-1.0</multiplier>
        <offset>0.0</offset>
        <robotNamespace>/</robotNamespace>
      </plugin>
      <plugin name='mimic_robotiq_85_5' filename='libroboticsgroup_gazebo_mimic_joint_plugin.so'>
        <joint>gripper_finger1_joint</joint>
        <mimicJoint>gripper_finger2_finger_tip_joint</mimicJoint>
        <multiplier>-1.0</multiplier>
        <offset>0.0</offset>
        <robotNamespace>/</robotNamespace>
      </plugin>
      <pose frame=''>7.66 2.6 0.17 0 -0 0</pose>
    </model>
    <model name='glue'>
      <link name='glue_link'>
        <inertial>
          <pose frame=''>0 0 0 0 -0 0</pose>
          <mass>0.08</mass>
          <inertia>
            <ixx>1</ixx>
            <ixy>0</ixy>
            <ixz>0</ixz>
            <iyy>1</iyy>
            <iyz>0</iyz>
            <izz>1</izz>
          </inertia>
        </inertial>
        <visual name='glue_visual'>
          <pose frame=''>0 0 0 0 -0 0</pose>
          <material>
            <script>
              <uri>model://glue/materials/scripts</uri>
              <uri>model://glue/materials/textures</uri>
              <name>glue</name>
            </script>
          </material>
          <geometry>
            <mesh>
              <uri>model://glue/meshes/glue.dae</uri>
            </mesh>
          </geometry>
        </visual>
        <collision name='glue_collision'>
          <pose frame=''>0 0.001 0.067 0 0 -0.95</pose>
          <geometry>
            <box>
              <size>0.06 0.032 0.133</size>
            </box>
          </geometry>
          <max_contacts>10</max_contacts>
          <surface>
            <contact>
              <ode/>
            </contact>
            <bounce/>
            <friction>
              <torsional>
                <ode/>
              </torsional>
              <ode/>
            </friction>
          </surface>
        </collision>
        <self_collide>0</self_collide>
        <enable_wind>0</enable_wind>
        <kinematic>0</kinematic>
      </link>
      <pose frame=''>7.97128 3.39399 0.87 0 -0 1.053</pose>
    </model>
    <model name='hand_cut3'>
      <link name='link_0'>
        <inertial>
          <mass>1</mass>
          <inertia>
            <ixx>0.166667</ixx>
            <ixy>0</ixy>
            <ixz>0</ixz>
            <iyy>0.166667</iyy>
            <iyz>0</iyz>
            <izz>0.166667</izz>
          </inertia>
          <pose frame=''>0 0 0 0 -0 0</pose>
        </inertial>
        <pose frame=''>0 0 0 0 -0 0</pose>
        <visual name='visual'>
          <pose frame=''>0 0 0 0 -0 0</pose>
          <geometry>
            <mesh>
              <uri>/home/kartik/model_editor_models/hand_cut3/meshes/hand_cut3.dae</uri>
              <scale>1 1 1</scale>
            </mesh>
          </geometry>
          <transparency>0</transparency>
          <cast_shadows>1</cast_shadows>
        </visual>
        <collision name='collision'>
          <laser_retro>0</laser_retro>
          <max_contacts>10</max_contacts>
          <pose frame=''>0 0 0 0 -0 0</pose>
          <geometry>
            <mesh>
              <uri>/home/kartik/model_editor_models/hand_cut3/meshes/hand_cut3.dae</uri>
              <scale>1 1 1</scale>
            </mesh>
          </geometry>
          <surface>
            <friction>
              <ode>
                <mu>1</mu>
                <mu2>1</mu2>
                <fdir1>0 0 0</fdir1>
                <slip1>0</slip1>
                <slip2>0</slip2>
              </ode>
              <torsional>
                <coefficient>1</coefficient>
                <patch_radius>0</patch_radius>
                <surface_radius>0</surface_radius>
                <use_patch_radius>1</use_patch_radius>
                <ode>
                  <slip>0</slip>
                </ode>
              </torsional>
            </friction>
            <bounce>
              <restitution_coefficient>0</restitution_coefficient>
              <threshold>1e+06</threshold>
            </bounce>
            <contact>
              <collide_without_contact>0</collide_without_contact>
              <collide_without_contact_bitmask>1</collide_without_contact_bitmask>
              <collide_bitmask>1</collide_bitmask>
              <ode>
                <soft_cfm>0</soft_cfm>
                <soft_erp>0.2</soft_erp>
                <kp>1e+13</kp>
                <kd>1</kd>
                <max_vel>0.01</max_vel>
                <min_depth>0</min_depth>
              </ode>
              <bullet>
                <split_impulse>1</split_impulse>
                <split_impulse_penetration_threshold>-0.01</split_impulse_penetration_threshold>
                <soft_cfm>0</soft_cfm>
                <soft_erp>0.2</soft_erp>
                <kp>1e+13</kp>
                <kd>1</kd>
              </bullet>
            </contact>
          </surface>
        </collision>
        <self_collide>0</self_collide>
        <enable_wind>0</enable_wind>
        <kinematic>0</kinematic>
      </link>
      <static>0</static>
      <allow_auto_disable>1</allow_auto_disable>
      <pose frame=''>6.25141 7.71239 0 0 -0 0</pose>
    </model>
    <state world_name='default'>
      <sim_time>58 427000000</sim_time>
      <real_time>180 466016453</real_time>
      <wall_time>1614363023 19983589</wall_time>
      <iterations>58427</iterations>
      <model name='battery'>
        <pose frame=''>8.10856 3.23928 0.872982 1.3e-05 4e-06 0</pose>
        <scale>1 1 1</scale>
        <link name='soap2_link'>
          <pose frame=''>8.10856 3.23928 0.872982 1.3e-05 4e-06 0</pose>
          <velocity>0 0 0 0 -0 0</velocity>
          <acceleration>0 0 -9.8 0 -0 0</acceleration>
          <wrench>0 0 -0.784 0 -0 0</wrench>
        </link>
      </model>
      <model name='coke_can'>
        <pose frame=''>7.84 3.23993 0.867667 -0.027939 0.00041 4.5e-05</pose>
        <scale>1 1 1</scale>
        <link name='link'>
          <pose frame=''>7.84 3.23993 0.867667 -0.027939 0.00041 4.5e-05</pose>
          <velocity>0 0 0 0 -0 0</velocity>
          <acceleration>-0.002339 0.014925 0.001623 -0.260379 -0.040932 -0.001547</acceleration>
          <wrench>-0.000912 0.005821 0.000633 0 -0 0</wrench>
        </link>
      </model>
      <model name='dropbox'>
        <pose frame=''>8.2 2.64 0.08 0 0 -1.6</pose>
        <scale>1 1 1</scale>
        <link name='link_0'>
          <pose frame=''>8.2 2.64 0.08 0 -0 3.11445</pose>
          <velocity>0 0 0 0 -0 0</velocity>
          <acceleration>0 0 0 0 -0 0</acceleration>
          <wrench>0 0 0 0 -0 0</wrench>
        </link>
      </model>
      <model name='ebot'>
        <pose frame=''>7.66355 2.6006 0.134995 -1e-06 -0 -0.001912</pose>
        <scale>1 1 1</scale>
        <link name='FWL'>
          <pose frame=''>7.86386 2.79238 0.18 -6e-06 -0.044291 0.004885</pose>
          <velocity>-0.000347 5.7e-05 0.001065 -0.000855 -0.003485 9.5e-05</velocity>
          <acceleration>-0.68336 0.118802 2.08702 1.39981 0.930724 -2.97309</acceleration>
          <wrench>-0.478352 0.083162 1.46091 0 -0 0</wrench>
        </link>
        <link name='FWR'>
          <pose frame=''>7.86573 2.41119 0.180001 -3.14158 0.84783 0.004895</pose>
          <velocity>-0.000323 -0.00023 0.00105 0.002304 -0.003207 9.7e-05</velocity>
          <acceleration>-0.631869 -0.45513 1.98532 1.05384 0.632852 3.01334</acceleration>
          <wrench>-0.442308 -0.318591 1.38972 0 -0 0</wrench>
        </link>
        <link name='RWL'>
          <pose frame=''>7.46387 2.79043 0.18 -1.5e-05 0.101219 0.004883</pose>
          <velocity>-0.000377 -0.000343 -0.001414 0.003334 -0.000106 5.3e-05</velocity>
          <acceleration>-0.73875 -0.674465 -2.66046 -2.78375 0.56779 3.13874</acceleration>
          <wrench>-0.517125 -0.472125 -1.86232 0 -0 0</wrench>
        </link>
        <link name='RWR'>
          <pose frame=''>7.46573 2.40923 0.179999 3.14159 0.618501 0.004882</pose>
          <velocity>-0.000348 -9.6e-05 -0.001186 0.000868 -0.000114 -3.3e-05</velocity>
          <acceleration>-0.68663 -0.181476 -2.41574 -1.49984 0.348051 2.9421</acceleration>
          <wrench>-0.480641 -0.127033 -1.69102 0 -0 0</wrench>
        </link>
        <link name='ebot_base'>
          <pose frame=''>7.66355 2.6006 0.134995 -1e-06 -0 -0.001912</pose>
          <velocity>-0.000356 -0.000258 -0.000142 3.3e-05 -0.000588 0.00012</velocity>
          <acceleration>-0.895185 -0.517558 -0.282578 0.066977 -1.17559 0.224163</acceleration>
          <wrench>-28.8631 -16.6874 -9.11106 0 -0 0</wrench>
        </link>
        <link name='forearm_link'>
          <pose frame=''>7.66532 2.61677 1.17014 -3.14138 1.04319 3.13876</pose>
          <velocity>0.00611 -0.003405 -0.002074 0.009322 0.007761 0.032806</velocity>
          <acceleration>1.79906 3.7366 -2.40578 0.036935 0.845095 -1.00553</acceleration>
          <wrench>4.09286 8.50077 -5.47314 0 -0 0</wrench>
        </link>
        <link name='gripper_finger1_finger_tip_link'>
          <pose frame=''>8.00127 2.91297 0.865103 0.530026 0.002133 1.56486</pose>
          <velocity>0.012641 0.011324 -0.003192 0.033425 -0.007638 -0.019596</velocity>
          <acceleration>12.6414 11.324 -3.19161 1.87608 -0.05417 -2.69767</acceleration>
          <wrench>0.247203 0.221442 -0.062412 0 -0 0</wrench>
        </link>
        <link name='gripper_finger1_inner_knuckle_link'>
          <pose frame=''>7.96857 2.87017 0.884203 0.530026 0.002153 1.56482</pose>
          <velocity>0.009786 0.013747 -0.003509 0.004692 -0.007837 -0.071032</velocity>
          <acceleration>9.78602 13.7466 -3.50929 -2.25656 -0.601963 -2.02785</acceleration>
          <wrench>0.293101 0.411723 -0.105107 0 -0 0</wrench>
        </link>
        <link name='gripper_finger1_knuckle_link'>
          <pose frame=''>7.98398 2.86354 0.875167 0.530002 0.002048 1.56474</pose>
          <velocity>0.009698 0.014075 -0.003467 0.016076 -0.002613 0.014743</velocity>
          <acceleration>19.3247 24.4612 2.19977 2.20364 -0.522602 -2.78781</acceleration>
          <wrench>0.88507 1.12032 0.100749 0 -0 0</wrench>
        </link>
        <link name='gripper_finger2_finger_tip_link'>
          <pose frame=''>7.91448 2.9136 0.915964 -2.6116 0.002144 1.56483</pose>
          <velocity>0.004498 0.007897 0.000187 0.020726 -0.00111 -0.012145</velocity>
          <acceleration>4.49844 7.89708 0.186694 -0.437516 -0.484895 2.34283</acceleration>
          <wrench>0.087967 0.154427 0.003651 0 -0 0</wrench>
        </link>
        <link name='gripper_finger2_inner_knuckle_link'>
          <pose frame=''>7.94666 2.87033 0.897044 -2.6116 0.002086 1.56493</pose>
          <velocity>0.009459 0.013012 -0.003577 0.090887 -0.001401 0.10523</velocity>
          <acceleration>9.45867 13.0121 -3.57716 1.76721 -1.46913 1.54884</acceleration>
          <wrench>0.283297 0.389725 -0.10714 0 -0 0</wrench>
        </link>
        <link name='gripper_finger2_knuckle_link'>
          <pose frame=''>7.93117 2.86393 0.906107 -2.61157 0.001982 1.56485</pose>
          <velocity>0.009387 0.012544 -0.003673 0.095072 -0.004186 0.15129</velocity>
          <acceleration>9.69835 9.18831 -3.96102 3.14087 -0.271863 1.35943</acceleration>
          <wrench>0.444185 0.420825 -0.181415 0 -0 0</wrench>
        </link>
        <link name='shoulder_link'>
          <pose frame=''>7.66355 2.6006 0.745154 1.7e-05 -1.9e-05 -0.002893</pose>
          <velocity>-0.000727 -0.000323 -9.6e-05 -0.00394 0.001923 0.000945</velocity>
          <acceleration>-1.4369 -0.63571 -0.19105 1.54867 -0.707065 -3.03701</acceleration>
          <wrench>-5.31651 -2.35213 -0.706886 0 -0 0</wrench>
        </link>
        <link name='upper_arm_link'>
          <pose frame=''>7.66394 2.73645 0.745144 -6.8e-05 0.004078 -0.002984</pose>
          <velocity>-0.001239 -0.000748 -0.002012 0.007474 0.007926 0.022477</velocity>
          <acceleration>-3.77605 -5.61644 -4.00817 2.41122 0.910855 0.043302</acceleration>
          <wrench>-31.6924 -47.1388 -33.6406 0 -0 0</wrench>
        </link>
        <link name='wrist_1_link'>
          <pose frame=''>8.00422 2.61572 0.972636 -3.14142 -0.530241 3.13852</pose>
          <velocity>0.010566 0.010381 -0.004844 0.015817 0.015895 0.043463</velocity>
          <acceleration>7.97392 15.9361 1.96321 2.84652 -0.569554 -0.02043</acceleration>
          <wrench>9.72021 19.4261 2.39316 0 -0 0</wrench>
        </link>
        <link name='wrist_2_link'>
          <pose frame=''>8.0045 2.70871 0.972618 -3.13925 -0.530211 3.13434</pose>
          <velocity>0.008796 0.012477 -0.005099 0.019467 -0.002393 0.026572</velocity>
          <acceleration>15.7092 21.4179 -3.34765 -3.03756 -1.453 2.6822</acceleration>
          <wrench>19.1495 26.1084 -4.08079 0 -0 0</wrench>
        </link>
        <link name='wrist_3_link'>
          <pose frame=''>7.95664 2.70883 0.890956 -3.13922 -0.530012 3.13432</pose>
          <velocity>0.011872 0.013075 -0.006131 0.017035 -0.003008 0.018619</velocity>
          <acceleration>18.788 22.0022 -1.69335 2.04018 -0.689816 0.715888</acceleration>
          <wrench>15.4975 18.1488 -1.39678 0 -0 0</wrench>
        </link>
      </model>
      <model name='glue'>
        <pose frame=''>7.97128 3.39399 0.869981 2e-06 1e-05 1.053</pose>
        <scale>1 1 1</scale>
        <link name='glue_link'>
          <pose frame=''>7.97128 3.39399 0.869981 2e-06 1e-05 1.053</pose>
          <velocity>0 0 0 0 -0 0</velocity>
          <acceleration>0 0 -9.8 0 -0 0</acceleration>
          <wrench>0 0 -0.784 0 -0 0</wrench>
        </link>
      </model>
      <model name='ground_plane'>
        <pose frame=''>0 0 0 0 -0 0</pose>
        <scale>1 1 1</scale>
        <link name='link'>
          <pose frame=''>0 0 0 0 -0 0</pose>
          <velocity>0 0 0 0 -0 0</velocity>
          <acceleration>0 0 0 0 -0 0</acceleration>
          <wrench>0 0 0 0 -0 0</wrench>
        </link>
      </model>
      <model name='hand_cut3'>
        <pose frame=''>6.25139 7.7124 -0.00313 0.00395 0.007362 2e-06</pose>
        <scale>1 1 1</scale>
        <link name='link_0'>
          <pose frame=''>6.25139 7.7124 -0.00313 0.00395 0.007362 2e-06</pose>
          <velocity>0 0 0 0 -0 0</velocity>
          <acceleration>0.002374 0.022119 -0.020198 0.78408 -0.758699 1e-06</acceleration>
          <wrench>0.002374 0.022119 -0.020198 0 -0 0</wrench>
        </link>
      </model>
      <model name='office'>
        <pose frame=''>0 0 0.08 0 -0 0</pose>
        <scale>1 1 1</scale>
        <link name='link'>
          <pose frame=''>0 0 0.08 0 -0 0</pose>
          <velocity>0 0 0 0 -0 0</velocity>
          <acceleration>0 0 0 0 -0 0</acceleration>
          <wrench>0 0 0 0 -0 0</wrench>
        </link>
      </model>
      <model name='table'>
        <pose frame=''>26.608 -3.569 0 0 -0 0.934</pose>
        <scale>1 1 1</scale>
        <link name='link'>
          <pose frame=''>26.608 -3.569 0 0 -0 0.934</pose>
          <velocity>0 0 0 0 -0 0</velocity>
          <acceleration>0 0 0 0 -0 0</acceleration>
          <wrench>0 0 0 0 -0 0</wrench>
        </link>
      </model>
      <light name='sun'>
        <pose frame=''>0 0 10 0 -0 0</pose>
      </light>
    </state>
    <gui fullscreen='0'>
      <camera name='user_camera'>
        <pose frame=''>5.28018 7.57622 0.613606 0 0.574269 0.123052</pose>
        <view_controller>orbit</view_controller>
        <projection_type>perspective</projection_type>
      </camera>
    </gui>
  </world>
</sdf>
